2022-11-22 14:50:13,486 INFO: errors [in D:\Assignments\Project Development Phase\Sprint 1\pet_App\app.py:37]
2022-11-22 14:50:20,412 ERROR: Exception on /register [GET] [in C:\Python\Python39\lib\site-packages\flask\app.py:1741]
Traceback (most recent call last):
  File "C:\Python\Python39\lib\site-packages\flask\app.py", line 2525, in wsgi_app
    response = self.full_dispatch_request()
  File "C:\Python\Python39\lib\site-packages\flask\app.py", line 1822, in full_dispatch_request
    rv = self.handle_user_exception(e)
  File "C:\Python\Python39\lib\site-packages\flask\app.py", line 1820, in full_dispatch_request
    rv = self.dispatch_request()
  File "C:\Python\Python39\lib\site-packages\flask\app.py", line 1796, in dispatch_request
    return self.ensure_sync(self.view_functions[rule.endpoint])(**view_args)
  File "D:\Assignments\Project Development Phase\Sprint 1\pet_App\app.py", line 63, in register
    hashed_password = Bcrypt.generate_password_hash(form.password.data)
TypeError: generate_password_hash() missing 1 required positional argument: 'password'
2022-11-22 14:52:22,536 ERROR: Exception on /register [GET] [in C:\Python\Python39\lib\site-packages\flask\app.py:1741]
Traceback (most recent call last):
  File "C:\Python\Python39\lib\site-packages\flask\app.py", line 2525, in wsgi_app
    response = self.full_dispatch_request()
  File "C:\Python\Python39\lib\site-packages\flask\app.py", line 1822, in full_dispatch_request
    rv = self.handle_user_exception(e)
  File "C:\Python\Python39\lib\site-packages\flask\app.py", line 1820, in full_dispatch_request
    rv = self.dispatch_request()
  File "C:\Python\Python39\lib\site-packages\flask\app.py", line 1796, in dispatch_request
    return self.ensure_sync(self.view_functions[rule.endpoint])(**view_args)
  File "D:\Assignments\Project Development Phase\Sprint 1\pet_App\app.py", line 63, in register
    hashed_password = Bcrypt.generate_password_hash(form.password.data)
TypeError: generate_password_hash() missing 1 required positional argument: 'password'
2022-11-22 14:52:37,560 INFO: errors [in D:\Assignments\Project Development Phase\Sprint 1\pet_App\app.py:37]
2022-11-22 14:52:41,907 ERROR: Exception on /register [GET] [in C:\Python\Python39\lib\site-packages\flask\app.py:1741]
Traceback (most recent call last):
  File "C:\Python\Python39\lib\site-packages\flask\app.py", line 2525, in wsgi_app
    response = self.full_dispatch_request()
  File "C:\Python\Python39\lib\site-packages\flask\app.py", line 1822, in full_dispatch_request
    rv = self.handle_user_exception(e)
  File "C:\Python\Python39\lib\site-packages\flask\app.py", line 1820, in full_dispatch_request
    rv = self.dispatch_request()
  File "C:\Python\Python39\lib\site-packages\flask\app.py", line 1796, in dispatch_request
    return self.ensure_sync(self.view_functions[rule.endpoint])(**view_args)
  File "D:\Assignments\Project Development Phase\Sprint 1\pet_App\app.py", line 63, in register
    hashed_password = Bcrypt.generate_password_hash(form.password.data)
TypeError: generate_password_hash() missing 1 required positional argument: 'password'
2022-11-22 14:53:10,810 ERROR: Exception on /register [GET] [in C:\Python\Python39\lib\site-packages\flask\app.py:1741]
Traceback (most recent call last):
  File "C:\Python\Python39\lib\site-packages\flask\app.py", line 2525, in wsgi_app
    response = self.full_dispatch_request()
  File "C:\Python\Python39\lib\site-packages\flask\app.py", line 1822, in full_dispatch_request
    rv = self.handle_user_exception(e)
  File "C:\Python\Python39\lib\site-packages\flask\app.py", line 1820, in full_dispatch_request
    rv = self.dispatch_request()
  File "C:\Python\Python39\lib\site-packages\flask\app.py", line 1796, in dispatch_request
    return self.ensure_sync(self.view_functions[rule.endpoint])(**view_args)
  File "D:\Assignments\Project Development Phase\Sprint 1\pet_App\app.py", line 63, in register
    hashed_password = Bcrypt.generate_password_hash(form.password)
TypeError: generate_password_hash() missing 1 required positional argument: 'password'
2022-11-22 14:54:59,736 ERROR: Exception on /register [GET] [in C:\Python\Python39\lib\site-packages\flask\app.py:1741]
Traceback (most recent call last):
  File "C:\Python\Python39\lib\site-packages\flask\app.py", line 2525, in wsgi_app
    response = self.full_dispatch_request()
  File "C:\Python\Python39\lib\site-packages\flask\app.py", line 1822, in full_dispatch_request
    rv = self.handle_user_exception(e)
  File "C:\Python\Python39\lib\site-packages\flask\app.py", line 1820, in full_dispatch_request
    rv = self.dispatch_request()
  File "C:\Python\Python39\lib\site-packages\flask\app.py", line 1796, in dispatch_request
    return self.ensure_sync(self.view_functions[rule.endpoint])(**view_args)
  File "D:\Assignments\Project Development Phase\Sprint 1\pet_App\app.py", line 63, in register
    submit = SubmitField("Register")
TypeError: generate_password_hash() missing 1 required positional argument: 'password'
2022-11-22 14:55:00,495 ERROR: Exception on /register [GET] [in C:\Python\Python39\lib\site-packages\flask\app.py:1741]
Traceback (most recent call last):
  File "C:\Python\Python39\lib\site-packages\flask\app.py", line 2525, in wsgi_app
    response = self.full_dispatch_request()
  File "C:\Python\Python39\lib\site-packages\flask\app.py", line 1822, in full_dispatch_request
    rv = self.handle_user_exception(e)
  File "C:\Python\Python39\lib\site-packages\flask\app.py", line 1820, in full_dispatch_request
    rv = self.dispatch_request()
  File "C:\Python\Python39\lib\site-packages\flask\app.py", line 1796, in dispatch_request
    return self.ensure_sync(self.view_functions[rule.endpoint])(**view_args)
  File "D:\Assignments\Project Development Phase\Sprint 1\pet_App\app.py", line 63, in register
    submit = SubmitField("Register")
TypeError: generate_password_hash() missing 1 required positional argument: 'password'
2022-11-22 14:55:45,124 INFO: errors [in D:\Assignments\Project Development Phase\Sprint 1\pet_App\app.py:43]
2022-11-22 14:55:46,931 ERROR: Exception on /register [GET] [in C:\Python\Python39\lib\site-packages\flask\app.py:1741]
Traceback (most recent call last):
  File "C:\Python\Python39\lib\site-packages\flask\app.py", line 2525, in wsgi_app
    response = self.full_dispatch_request()
  File "C:\Python\Python39\lib\site-packages\flask\app.py", line 1822, in full_dispatch_request
    rv = self.handle_user_exception(e)
  File "C:\Python\Python39\lib\site-packages\flask\app.py", line 1820, in full_dispatch_request
    rv = self.dispatch_request()
  File "C:\Python\Python39\lib\site-packages\flask\app.py", line 1796, in dispatch_request
    return self.ensure_sync(self.view_functions[rule.endpoint])(**view_args)
  File "D:\Assignments\Project Development Phase\Sprint 1\pet_App\app.py", line 102, in register
    hashed_password = Bcrypt.generate_password_hash(password)
TypeError: generate_password_hash() missing 1 required positional argument: 'password'
2022-11-22 14:56:22,444 INFO: errors [in D:\Assignments\Project Development Phase\Sprint 1\pet_App\app.py:43]
2022-11-22 14:56:31,943 ERROR: Exception on /register [GET] [in C:\Python\Python39\lib\site-packages\flask\app.py:1741]
Traceback (most recent call last):
  File "C:\Python\Python39\lib\site-packages\flask\app.py", line 2525, in wsgi_app
    response = self.full_dispatch_request()
  File "C:\Python\Python39\lib\site-packages\flask\app.py", line 1822, in full_dispatch_request
    rv = self.handle_user_exception(e)
  File "C:\Python\Python39\lib\site-packages\flask\app.py", line 1820, in full_dispatch_request
    rv = self.dispatch_request()
  File "C:\Python\Python39\lib\site-packages\flask\app.py", line 1796, in dispatch_request
    return self.ensure_sync(self.view_functions[rule.endpoint])(**view_args)
  File "D:\Assignments\Project Development Phase\Sprint 1\pet_App\app.py", line 102, in register
    hashed_password = Bcrypt.generate_password_hash(password)
TypeError: generate_password_hash() missing 1 required positional argument: 'password'
2022-11-22 14:56:48,909 ERROR: Exception on /register [GET] [in C:\Python\Python39\lib\site-packages\flask\app.py:1741]
Traceback (most recent call last):
  File "C:\Python\Python39\lib\site-packages\flask\app.py", line 2525, in wsgi_app
    response = self.full_dispatch_request()
  File "C:\Python\Python39\lib\site-packages\flask\app.py", line 1822, in full_dispatch_request
    rv = self.handle_user_exception(e)
  File "C:\Python\Python39\lib\site-packages\flask\app.py", line 1820, in full_dispatch_request
    rv = self.dispatch_request()
  File "C:\Python\Python39\lib\site-packages\flask\app.py", line 1796, in dispatch_request
    return self.ensure_sync(self.view_functions[rule.endpoint])(**view_args)
  File "D:\Assignments\Project Development Phase\Sprint 1\pet_App\app.py", line 102, in register
    # hashed_password = Bcrypt.generate_password_hash(password)
TypeError: generate_password_hash() missing 1 required positional argument: 'password'
2022-11-22 14:56:49,875 ERROR: Exception on /register [GET] [in C:\Python\Python39\lib\site-packages\flask\app.py:1741]
Traceback (most recent call last):
  File "C:\Python\Python39\lib\site-packages\flask\app.py", line 2525, in wsgi_app
    response = self.full_dispatch_request()
  File "C:\Python\Python39\lib\site-packages\flask\app.py", line 1822, in full_dispatch_request
    rv = self.handle_user_exception(e)
  File "C:\Python\Python39\lib\site-packages\flask\app.py", line 1820, in full_dispatch_request
    rv = self.dispatch_request()
  File "C:\Python\Python39\lib\site-packages\flask\app.py", line 1796, in dispatch_request
    return self.ensure_sync(self.view_functions[rule.endpoint])(**view_args)
  File "D:\Assignments\Project Development Phase\Sprint 1\pet_App\app.py", line 102, in register
    # hashed_password = Bcrypt.generate_password_hash(password)
TypeError: generate_password_hash() missing 1 required positional argument: 'password'
2022-11-22 14:56:50,310 ERROR: Exception on /register [GET] [in C:\Python\Python39\lib\site-packages\flask\app.py:1741]
Traceback (most recent call last):
  File "C:\Python\Python39\lib\site-packages\flask\app.py", line 2525, in wsgi_app
    response = self.full_dispatch_request()
  File "C:\Python\Python39\lib\site-packages\flask\app.py", line 1822, in full_dispatch_request
    rv = self.handle_user_exception(e)
  File "C:\Python\Python39\lib\site-packages\flask\app.py", line 1820, in full_dispatch_request
    rv = self.dispatch_request()
  File "C:\Python\Python39\lib\site-packages\flask\app.py", line 1796, in dispatch_request
    return self.ensure_sync(self.view_functions[rule.endpoint])(**view_args)
  File "D:\Assignments\Project Development Phase\Sprint 1\pet_App\app.py", line 102, in register
    # hashed_password = Bcrypt.generate_password_hash(password)
TypeError: generate_password_hash() missing 1 required positional argument: 'password'
2022-11-22 14:56:50,490 ERROR: Exception on /register [GET] [in C:\Python\Python39\lib\site-packages\flask\app.py:1741]
Traceback (most recent call last):
  File "C:\Python\Python39\lib\site-packages\flask\app.py", line 2525, in wsgi_app
    response = self.full_dispatch_request()
  File "C:\Python\Python39\lib\site-packages\flask\app.py", line 1822, in full_dispatch_request
    rv = self.handle_user_exception(e)
  File "C:\Python\Python39\lib\site-packages\flask\app.py", line 1820, in full_dispatch_request
    rv = self.dispatch_request()
  File "C:\Python\Python39\lib\site-packages\flask\app.py", line 1796, in dispatch_request
    return self.ensure_sync(self.view_functions[rule.endpoint])(**view_args)
  File "D:\Assignments\Project Development Phase\Sprint 1\pet_App\app.py", line 102, in register
    # hashed_password = Bcrypt.generate_password_hash(password)
TypeError: generate_password_hash() missing 1 required positional argument: 'password'
2022-11-22 14:56:58,160 INFO: errors [in D:\Assignments\Project Development Phase\Sprint 1\pet_App\app.py:43]
2022-11-22 14:56:58,318 ERROR: Exception on /register [GET] [in C:\Python\Python39\lib\site-packages\flask\app.py:1741]
Traceback (most recent call last):
  File "C:\Python\Python39\lib\site-packages\flask\app.py", line 2525, in wsgi_app
    response = self.full_dispatch_request()
  File "C:\Python\Python39\lib\site-packages\flask\app.py", line 1822, in full_dispatch_request
    rv = self.handle_user_exception(e)
  File "C:\Python\Python39\lib\site-packages\flask\app.py", line 1820, in full_dispatch_request
    rv = self.dispatch_request()
  File "C:\Python\Python39\lib\site-packages\flask\app.py", line 1796, in dispatch_request
    return self.ensure_sync(self.view_functions[rule.endpoint])(**view_args)
  File "D:\Assignments\Project Development Phase\Sprint 1\pet_App\app.py", line 107, in register
    return render_template('forms/register.html', form=form)
NameError: name 'form' is not defined
2022-11-22 14:56:58,724 ERROR: Exception on /register [GET] [in C:\Python\Python39\lib\site-packages\flask\app.py:1741]
Traceback (most recent call last):
  File "C:\Python\Python39\lib\site-packages\flask\app.py", line 2525, in wsgi_app
    response = self.full_dispatch_request()
  File "C:\Python\Python39\lib\site-packages\flask\app.py", line 1822, in full_dispatch_request
    rv = self.handle_user_exception(e)
  File "C:\Python\Python39\lib\site-packages\flask\app.py", line 1820, in full_dispatch_request
    rv = self.dispatch_request()
  File "C:\Python\Python39\lib\site-packages\flask\app.py", line 1796, in dispatch_request
    return self.ensure_sync(self.view_functions[rule.endpoint])(**view_args)
  File "D:\Assignments\Project Development Phase\Sprint 1\pet_App\app.py", line 107, in register
    return render_template('forms/register.html', form=form)
NameError: name 'form' is not defined
2022-11-22 14:56:59,325 ERROR: Exception on /register [GET] [in C:\Python\Python39\lib\site-packages\flask\app.py:1741]
Traceback (most recent call last):
  File "C:\Python\Python39\lib\site-packages\flask\app.py", line 2525, in wsgi_app
    response = self.full_dispatch_request()
  File "C:\Python\Python39\lib\site-packages\flask\app.py", line 1822, in full_dispatch_request
    rv = self.handle_user_exception(e)
  File "C:\Python\Python39\lib\site-packages\flask\app.py", line 1820, in full_dispatch_request
    rv = self.dispatch_request()
  File "C:\Python\Python39\lib\site-packages\flask\app.py", line 1796, in dispatch_request
    return self.ensure_sync(self.view_functions[rule.endpoint])(**view_args)
  File "D:\Assignments\Project Development Phase\Sprint 1\pet_App\app.py", line 107, in register
    return render_template('forms/register.html', form=form)
NameError: name 'form' is not defined
2022-11-22 14:57:02,653 ERROR: Exception on /register [GET] [in C:\Python\Python39\lib\site-packages\flask\app.py:1741]
Traceback (most recent call last):
  File "C:\Python\Python39\lib\site-packages\flask\app.py", line 2525, in wsgi_app
    response = self.full_dispatch_request()
  File "C:\Python\Python39\lib\site-packages\flask\app.py", line 1822, in full_dispatch_request
    rv = self.handle_user_exception(e)
  File "C:\Python\Python39\lib\site-packages\flask\app.py", line 1820, in full_dispatch_request
    rv = self.dispatch_request()
  File "C:\Python\Python39\lib\site-packages\flask\app.py", line 1796, in dispatch_request
    return self.ensure_sync(self.view_functions[rule.endpoint])(**view_args)
  File "D:\Assignments\Project Development Phase\Sprint 1\pet_App\app.py", line 107, in register
    return render_template('forms/register.html', form=form)
NameError: name 'form' is not defined
2022-11-22 14:58:45,391 ERROR: Exception on /register [GET] [in C:\Python\Python39\lib\site-packages\flask\app.py:1741]
Traceback (most recent call last):
  File "C:\Python\Python39\lib\site-packages\flask\app.py", line 2525, in wsgi_app
    response = self.full_dispatch_request()
  File "C:\Python\Python39\lib\site-packages\flask\app.py", line 1822, in full_dispatch_request
    rv = self.handle_user_exception(e)
  File "C:\Python\Python39\lib\site-packages\flask\app.py", line 1820, in full_dispatch_request
    rv = self.dispatch_request()
  File "C:\Python\Python39\lib\site-packages\flask\app.py", line 1796, in dispatch_request
    return self.ensure_sync(self.view_functions[rule.endpoint])(**view_args)
  File "D:\Assignments\Project Development Phase\Sprint 1\pet_App\app.py", line 107, in register
NameError: name 'form' is not defined
2022-11-22 14:58:46,545 ERROR: Exception on /register [GET] [in C:\Python\Python39\lib\site-packages\flask\app.py:1741]
Traceback (most recent call last):
  File "C:\Python\Python39\lib\site-packages\flask\app.py", line 2525, in wsgi_app
    response = self.full_dispatch_request()
  File "C:\Python\Python39\lib\site-packages\flask\app.py", line 1822, in full_dispatch_request
    rv = self.handle_user_exception(e)
  File "C:\Python\Python39\lib\site-packages\flask\app.py", line 1820, in full_dispatch_request
    rv = self.dispatch_request()
  File "C:\Python\Python39\lib\site-packages\flask\app.py", line 1796, in dispatch_request
    return self.ensure_sync(self.view_functions[rule.endpoint])(**view_args)
  File "D:\Assignments\Project Development Phase\Sprint 1\pet_App\app.py", line 107, in register
NameError: name 'form' is not defined
2022-11-22 14:58:50,436 ERROR: Exception on /register [GET] [in C:\Python\Python39\lib\site-packages\flask\app.py:1741]
Traceback (most recent call last):
  File "C:\Python\Python39\lib\site-packages\flask\app.py", line 2525, in wsgi_app
    response = self.full_dispatch_request()
  File "C:\Python\Python39\lib\site-packages\flask\app.py", line 1822, in full_dispatch_request
    rv = self.handle_user_exception(e)
  File "C:\Python\Python39\lib\site-packages\flask\app.py", line 1820, in full_dispatch_request
    rv = self.dispatch_request()
  File "C:\Python\Python39\lib\site-packages\flask\app.py", line 1796, in dispatch_request
    return self.ensure_sync(self.view_functions[rule.endpoint])(**view_args)
  File "D:\Assignments\Project Development Phase\Sprint 1\pet_App\app.py", line 107, in register
NameError: name 'form' is not defined
2022-11-22 14:59:21,108 ERROR: Exception on /register [GET] [in C:\Python\Python39\lib\site-packages\flask\app.py:1741]
Traceback (most recent call last):
  File "C:\Python\Python39\lib\site-packages\flask\app.py", line 2525, in wsgi_app
    response = self.full_dispatch_request()
  File "C:\Python\Python39\lib\site-packages\flask\app.py", line 1822, in full_dispatch_request
    rv = self.handle_user_exception(e)
  File "C:\Python\Python39\lib\site-packages\flask\app.py", line 1820, in full_dispatch_request
    rv = self.dispatch_request()
  File "C:\Python\Python39\lib\site-packages\flask\app.py", line 1796, in dispatch_request
    return self.ensure_sync(self.view_functions[rule.endpoint])(**view_args)
  File "D:\Assignments\Project Development Phase\Sprint 1\pet_App\app.py", line 107, in register
NameError: name 'form' is not defined
2022-11-22 14:59:21,730 ERROR: Exception on /register [GET] [in C:\Python\Python39\lib\site-packages\flask\app.py:1741]
Traceback (most recent call last):
  File "C:\Python\Python39\lib\site-packages\flask\app.py", line 2525, in wsgi_app
    response = self.full_dispatch_request()
  File "C:\Python\Python39\lib\site-packages\flask\app.py", line 1822, in full_dispatch_request
    rv = self.handle_user_exception(e)
  File "C:\Python\Python39\lib\site-packages\flask\app.py", line 1820, in full_dispatch_request
    rv = self.dispatch_request()
  File "C:\Python\Python39\lib\site-packages\flask\app.py", line 1796, in dispatch_request
    return self.ensure_sync(self.view_functions[rule.endpoint])(**view_args)
  File "D:\Assignments\Project Development Phase\Sprint 1\pet_App\app.py", line 107, in register
NameError: name 'form' is not defined
2022-11-22 14:59:22,061 ERROR: Exception on /register [GET] [in C:\Python\Python39\lib\site-packages\flask\app.py:1741]
Traceback (most recent call last):
  File "C:\Python\Python39\lib\site-packages\flask\app.py", line 2525, in wsgi_app
    response = self.full_dispatch_request()
  File "C:\Python\Python39\lib\site-packages\flask\app.py", line 1822, in full_dispatch_request
    rv = self.handle_user_exception(e)
  File "C:\Python\Python39\lib\site-packages\flask\app.py", line 1820, in full_dispatch_request
    rv = self.dispatch_request()
  File "C:\Python\Python39\lib\site-packages\flask\app.py", line 1796, in dispatch_request
    return self.ensure_sync(self.view_functions[rule.endpoint])(**view_args)
  File "D:\Assignments\Project Development Phase\Sprint 1\pet_App\app.py", line 107, in register
NameError: name 'form' is not defined
2022-11-22 14:59:22,345 ERROR: Exception on /register [GET] [in C:\Python\Python39\lib\site-packages\flask\app.py:1741]
Traceback (most recent call last):
  File "C:\Python\Python39\lib\site-packages\flask\app.py", line 2525, in wsgi_app
    response = self.full_dispatch_request()
  File "C:\Python\Python39\lib\site-packages\flask\app.py", line 1822, in full_dispatch_request
    rv = self.handle_user_exception(e)
  File "C:\Python\Python39\lib\site-packages\flask\app.py", line 1820, in full_dispatch_request
    rv = self.dispatch_request()
  File "C:\Python\Python39\lib\site-packages\flask\app.py", line 1796, in dispatch_request
    return self.ensure_sync(self.view_functions[rule.endpoint])(**view_args)
  File "D:\Assignments\Project Development Phase\Sprint 1\pet_App\app.py", line 107, in register
NameError: name 'form' is not defined
2022-11-22 15:34:43,781 ERROR: Exception on /register [GET] [in C:\Python\Python39\lib\site-packages\flask\app.py:1741]
Traceback (most recent call last):
  File "C:\Python\Python39\lib\site-packages\flask\app.py", line 2525, in wsgi_app
    response = self.full_dispatch_request()
  File "C:\Python\Python39\lib\site-packages\flask\app.py", line 1822, in full_dispatch_request
    rv = self.handle_user_exception(e)
  File "C:\Python\Python39\lib\site-packages\flask\app.py", line 1820, in full_dispatch_request
    rv = self.dispatch_request()
  File "C:\Python\Python39\lib\site-packages\flask\app.py", line 1796, in dispatch_request
    return self.ensure_sync(self.view_functions[rule.endpoint])(**view_args)
  File "D:\Assignments\Project Development Phase\Sprint 1\pet_App\app.py", line 107, in register
NameError: name 'form' is not defined
2022-11-22 15:34:44,973 ERROR: Exception on /register [GET] [in C:\Python\Python39\lib\site-packages\flask\app.py:1741]
Traceback (most recent call last):
  File "C:\Python\Python39\lib\site-packages\flask\app.py", line 2525, in wsgi_app
    response = self.full_dispatch_request()
  File "C:\Python\Python39\lib\site-packages\flask\app.py", line 1822, in full_dispatch_request
    rv = self.handle_user_exception(e)
  File "C:\Python\Python39\lib\site-packages\flask\app.py", line 1820, in full_dispatch_request
    rv = self.dispatch_request()
  File "C:\Python\Python39\lib\site-packages\flask\app.py", line 1796, in dispatch_request
    return self.ensure_sync(self.view_functions[rule.endpoint])(**view_args)
  File "D:\Assignments\Project Development Phase\Sprint 1\pet_App\app.py", line 107, in register
NameError: name 'form' is not defined
2022-11-22 15:44:44,035 INFO: errors [in D:\Assignments\Project Development Phase\Sprint 1\pet_App\app.py:41]
2022-11-22 15:49:11,746 INFO: errors [in D:\Assignments\Project Development Phase\Sprint 1\pet_App\app.py:41]
2022-11-22 15:52:31,158 INFO: errors [in D:\Assignments\Project Development Phase\Sprint 1\pet_App\app.py:41]
2022-11-22 15:55:07,351 INFO: errors [in D:\Assignments\Project Development Phase\Sprint 1\pet_App\app.py:41]
2022-11-22 15:58:26,182 INFO: errors [in D:\Assignments\Project Development Phase\Sprint 1\pet_App\app.py:41]
2022-11-22 16:03:55,212 INFO: errors [in D:\Assignments\Project Development Phase\Sprint 1\pet_App\app.py:41]
2022-11-22 16:04:07,153 ERROR: Exception on /register [GET] [in C:\Python\Python39\lib\site-packages\flask\app.py:1741]
Traceback (most recent call last):
  File "C:\Python\Python39\lib\site-packages\flask\app.py", line 2525, in wsgi_app
    response = self.full_dispatch_request()
  File "C:\Python\Python39\lib\site-packages\flask\app.py", line 1822, in full_dispatch_request
    rv = self.handle_user_exception(e)
  File "C:\Python\Python39\lib\site-packages\flask\app.py", line 1820, in full_dispatch_request
    rv = self.dispatch_request()
  File "C:\Python\Python39\lib\site-packages\flask\app.py", line 1796, in dispatch_request
    return self.ensure_sync(self.view_functions[rule.endpoint])(**view_args)
  File "D:\Assignments\Project Development Phase\Sprint 1\pet_App\app.py", line 78, in register
    if form.validate_on_submit():
AttributeError: 'RegisterForm' object has no attribute 'validate_on_submit'
2022-11-22 16:04:46,231 INFO: errors [in D:\Assignments\Project Development Phase\Sprint 1\pet_App\app.py:41]
2022-11-22 16:17:07,727 INFO: errors [in D:\Assignments\Project Development Phase\Sprint 1\pet_App\app.py:41]
2022-11-22 16:31:25,050 ERROR: Exception on /register [GET] [in C:\Python\Python39\lib\site-packages\flask\app.py:1741]
Traceback (most recent call last):
  File "C:\Python\Python39\lib\site-packages\flask\app.py", line 2525, in wsgi_app
    response = self.full_dispatch_request()
  File "C:\Python\Python39\lib\site-packages\flask\app.py", line 1822, in full_dispatch_request
    rv = self.handle_user_exception(e)
  File "C:\Python\Python39\lib\site-packages\flask\app.py", line 1820, in full_dispatch_request
    rv = self.dispatch_request()
  File "C:\Python\Python39\lib\site-packages\flask\app.py", line 1796, in dispatch_request
    return self.ensure_sync(self.view_functions[rule.endpoint])(**view_args)
  File "D:\Assignments\Project Development Phase\Sprint 1\pet_App\app.py", line 84, in register
    new_user = User(username=form.username.data, password=hashed_password)
  File "C:\Python\Python39\lib\site-packages\flask\templating.py", line 146, in render_template
    template = app.jinja_env.get_or_select_template(template_name_or_list)
  File "C:\Python\Python39\lib\site-packages\jinja2\environment.py", line 1068, in get_or_select_template
    return self.get_template(template_name_or_list, parent, globals)
  File "C:\Python\Python39\lib\site-packages\jinja2\environment.py", line 997, in get_template
    return self._load_template(name, globals)
  File "C:\Python\Python39\lib\site-packages\jinja2\environment.py", line 958, in _load_template
    template = self.loader.load(self, name, self.make_globals(globals))
  File "C:\Python\Python39\lib\site-packages\jinja2\loaders.py", line 125, in load
    source, filename, uptodate = self.get_source(environment, name)
  File "C:\Python\Python39\lib\site-packages\flask\templating.py", line 62, in get_source
    return self._get_source_fast(environment, template)
  File "C:\Python\Python39\lib\site-packages\flask\templating.py", line 98, in _get_source_fast
    raise TemplateNotFound(template)
jinja2.exceptions.TemplateNotFound: forms/main.html
2022-11-22 16:31:27,298 ERROR: Exception on /register [GET] [in C:\Python\Python39\lib\site-packages\flask\app.py:1741]
Traceback (most recent call last):
  File "C:\Python\Python39\lib\site-packages\flask\app.py", line 2525, in wsgi_app
    response = self.full_dispatch_request()
  File "C:\Python\Python39\lib\site-packages\flask\app.py", line 1822, in full_dispatch_request
    rv = self.handle_user_exception(e)
  File "C:\Python\Python39\lib\site-packages\flask\app.py", line 1820, in full_dispatch_request
    rv = self.dispatch_request()
  File "C:\Python\Python39\lib\site-packages\flask\app.py", line 1796, in dispatch_request
    return self.ensure_sync(self.view_functions[rule.endpoint])(**view_args)
  File "D:\Assignments\Project Development Phase\Sprint 1\pet_App\app.py", line 84, in register
    new_user = User(username=form.username.data, password=hashed_password)
  File "C:\Python\Python39\lib\site-packages\flask\templating.py", line 146, in render_template
    template = app.jinja_env.get_or_select_template(template_name_or_list)
  File "C:\Python\Python39\lib\site-packages\jinja2\environment.py", line 1068, in get_or_select_template
    return self.get_template(template_name_or_list, parent, globals)
  File "C:\Python\Python39\lib\site-packages\jinja2\environment.py", line 997, in get_template
    return self._load_template(name, globals)
  File "C:\Python\Python39\lib\site-packages\jinja2\environment.py", line 958, in _load_template
    template = self.loader.load(self, name, self.make_globals(globals))
  File "C:\Python\Python39\lib\site-packages\jinja2\loaders.py", line 125, in load
    source, filename, uptodate = self.get_source(environment, name)
  File "C:\Python\Python39\lib\site-packages\flask\templating.py", line 62, in get_source
    return self._get_source_fast(environment, template)
  File "C:\Python\Python39\lib\site-packages\flask\templating.py", line 98, in _get_source_fast
    raise TemplateNotFound(template)
jinja2.exceptions.TemplateNotFound: forms/main.html
2022-11-22 16:31:27,477 ERROR: Exception on /register [GET] [in C:\Python\Python39\lib\site-packages\flask\app.py:1741]
Traceback (most recent call last):
  File "C:\Python\Python39\lib\site-packages\flask\app.py", line 2525, in wsgi_app
    response = self.full_dispatch_request()
  File "C:\Python\Python39\lib\site-packages\flask\app.py", line 1822, in full_dispatch_request
    rv = self.handle_user_exception(e)
  File "C:\Python\Python39\lib\site-packages\flask\app.py", line 1820, in full_dispatch_request
    rv = self.dispatch_request()
  File "C:\Python\Python39\lib\site-packages\flask\app.py", line 1796, in dispatch_request
    return self.ensure_sync(self.view_functions[rule.endpoint])(**view_args)
  File "D:\Assignments\Project Development Phase\Sprint 1\pet_App\app.py", line 84, in register
    new_user = User(username=form.username.data, password=hashed_password)
  File "C:\Python\Python39\lib\site-packages\flask\templating.py", line 146, in render_template
    template = app.jinja_env.get_or_select_template(template_name_or_list)
  File "C:\Python\Python39\lib\site-packages\jinja2\environment.py", line 1068, in get_or_select_template
    return self.get_template(template_name_or_list, parent, globals)
  File "C:\Python\Python39\lib\site-packages\jinja2\environment.py", line 997, in get_template
    return self._load_template(name, globals)
  File "C:\Python\Python39\lib\site-packages\jinja2\environment.py", line 958, in _load_template
    template = self.loader.load(self, name, self.make_globals(globals))
  File "C:\Python\Python39\lib\site-packages\jinja2\loaders.py", line 125, in load
    source, filename, uptodate = self.get_source(environment, name)
  File "C:\Python\Python39\lib\site-packages\flask\templating.py", line 62, in get_source
    return self._get_source_fast(environment, template)
  File "C:\Python\Python39\lib\site-packages\flask\templating.py", line 98, in _get_source_fast
    raise TemplateNotFound(template)
jinja2.exceptions.TemplateNotFound: forms/main.html
2022-11-22 16:32:11,487 INFO: errors [in D:\Assignments\Project Development Phase\Sprint 1\pet_App\app.py:45]
2022-11-22 16:32:12,379 ERROR: Exception on /register [GET] [in C:\Python\Python39\lib\site-packages\flask\app.py:1741]
Traceback (most recent call last):
  File "C:\Python\Python39\lib\site-packages\flask\app.py", line 2525, in wsgi_app
    response = self.full_dispatch_request()
  File "C:\Python\Python39\lib\site-packages\flask\app.py", line 1822, in full_dispatch_request
    rv = self.handle_user_exception(e)
  File "C:\Python\Python39\lib\site-packages\flask\app.py", line 1820, in full_dispatch_request
    rv = self.dispatch_request()
  File "C:\Python\Python39\lib\site-packages\flask\app.py", line 1796, in dispatch_request
    return self.ensure_sync(self.view_functions[rule.endpoint])(**view_args)
  File "D:\Assignments\Project Development Phase\Sprint 1\pet_App\app.py", line 88, in register
    return render_template('forms/main.html', form=form)
  File "C:\Python\Python39\lib\site-packages\flask\templating.py", line 146, in render_template
    template = app.jinja_env.get_or_select_template(template_name_or_list)
  File "C:\Python\Python39\lib\site-packages\jinja2\environment.py", line 1068, in get_or_select_template
    return self.get_template(template_name_or_list, parent, globals)
  File "C:\Python\Python39\lib\site-packages\jinja2\environment.py", line 997, in get_template
    return self._load_template(name, globals)
  File "C:\Python\Python39\lib\site-packages\jinja2\environment.py", line 958, in _load_template
    template = self.loader.load(self, name, self.make_globals(globals))
  File "C:\Python\Python39\lib\site-packages\jinja2\loaders.py", line 125, in load
    source, filename, uptodate = self.get_source(environment, name)
  File "C:\Python\Python39\lib\site-packages\flask\templating.py", line 62, in get_source
    return self._get_source_fast(environment, template)
  File "C:\Python\Python39\lib\site-packages\flask\templating.py", line 98, in _get_source_fast
    raise TemplateNotFound(template)
jinja2.exceptions.TemplateNotFound: forms/main.html
2022-11-22 16:41:57,131 INFO: errors [in D:\Assignments\Project Development Phase\Sprint 1\pet_App\app.py:45]
2022-11-22 16:42:00,777 ERROR: Exception on / [GET] [in C:\Python\Python39\lib\site-packages\flask\app.py:1741]
Traceback (most recent call last):
  File "C:\Python\Python39\lib\site-packages\flask\app.py", line 2525, in wsgi_app
    response = self.full_dispatch_request()
  File "C:\Python\Python39\lib\site-packages\flask\app.py", line 1822, in full_dispatch_request
    rv = self.handle_user_exception(e)
  File "C:\Python\Python39\lib\site-packages\flask\app.py", line 1820, in full_dispatch_request
    rv = self.dispatch_request()
  File "C:\Python\Python39\lib\site-packages\flask\app.py", line 1796, in dispatch_request
    return self.ensure_sync(self.view_functions[rule.endpoint])(**view_args)
  File "D:\Assignments\Project Development Phase\Sprint 1\pet_App\app.py", line 62, in home
    return render_template('pages/placeholder.home.html')
  File "C:\Python\Python39\lib\site-packages\flask\templating.py", line 147, in render_template
    return _render(app, template, context)
  File "C:\Python\Python39\lib\site-packages\flask\templating.py", line 128, in _render
    app.update_template_context(context)
  File "C:\Python\Python39\lib\site-packages\flask\app.py", line 994, in update_template_context
    context.update(func())
  File "C:\Python\Python39\lib\site-packages\flask_login\utils.py", line 407, in _user_context_processor
    return dict(current_user=_get_user())
  File "C:\Python\Python39\lib\site-packages\flask_login\utils.py", line 372, in _get_user
    current_app.login_manager._load_user()
  File "C:\Python\Python39\lib\site-packages\flask_login\login_manager.py", line 347, in _load_user
    raise Exception(
Exception: Missing user_loader or request_loader. Refer to http://flask-login.readthedocs.io/#how-it-works for more info.
2022-11-22 16:42:00,817 ERROR: Exception on / [GET] [in C:\Python\Python39\lib\site-packages\flask\app.py:1741]
Traceback (most recent call last):
  File "C:\Python\Python39\lib\site-packages\flask\app.py", line 2525, in wsgi_app
    response = self.full_dispatch_request()
  File "C:\Python\Python39\lib\site-packages\flask\app.py", line 1822, in full_dispatch_request
    rv = self.handle_user_exception(e)
  File "C:\Python\Python39\lib\site-packages\flask\app.py", line 1820, in full_dispatch_request
    rv = self.dispatch_request()
  File "C:\Python\Python39\lib\site-packages\flask\app.py", line 1796, in dispatch_request
    return self.ensure_sync(self.view_functions[rule.endpoint])(**view_args)
  File "D:\Assignments\Project Development Phase\Sprint 1\pet_App\app.py", line 62, in home
    return render_template('pages/placeholder.home.html')
  File "C:\Python\Python39\lib\site-packages\flask\templating.py", line 147, in render_template
    return _render(app, template, context)
  File "C:\Python\Python39\lib\site-packages\flask\templating.py", line 128, in _render
    app.update_template_context(context)
  File "C:\Python\Python39\lib\site-packages\flask\app.py", line 994, in update_template_context
    context.update(func())
  File "C:\Python\Python39\lib\site-packages\flask_login\utils.py", line 407, in _user_context_processor
    return dict(current_user=_get_user())
  File "C:\Python\Python39\lib\site-packages\flask_login\utils.py", line 372, in _get_user
    current_app.login_manager._load_user()
  File "C:\Python\Python39\lib\site-packages\flask_login\login_manager.py", line 347, in _load_user
    raise Exception(
Exception: Missing user_loader or request_loader. Refer to http://flask-login.readthedocs.io/#how-it-works for more info.
2022-11-22 16:42:06,565 ERROR: Exception on / [GET] [in C:\Python\Python39\lib\site-packages\flask\app.py:1741]
Traceback (most recent call last):
  File "C:\Python\Python39\lib\site-packages\flask\app.py", line 2525, in wsgi_app
    response = self.full_dispatch_request()
  File "C:\Python\Python39\lib\site-packages\flask\app.py", line 1822, in full_dispatch_request
    rv = self.handle_user_exception(e)
  File "C:\Python\Python39\lib\site-packages\flask\app.py", line 1820, in full_dispatch_request
    rv = self.dispatch_request()
  File "C:\Python\Python39\lib\site-packages\flask\app.py", line 1796, in dispatch_request
    return self.ensure_sync(self.view_functions[rule.endpoint])(**view_args)
  File "D:\Assignments\Project Development Phase\Sprint 1\pet_App\app.py", line 62, in home
    return render_template('pages/placeholder.home.html')
  File "C:\Python\Python39\lib\site-packages\flask\templating.py", line 147, in render_template
    return _render(app, template, context)
  File "C:\Python\Python39\lib\site-packages\flask\templating.py", line 128, in _render
    app.update_template_context(context)
  File "C:\Python\Python39\lib\site-packages\flask\app.py", line 994, in update_template_context
    context.update(func())
  File "C:\Python\Python39\lib\site-packages\flask_login\utils.py", line 407, in _user_context_processor
    return dict(current_user=_get_user())
  File "C:\Python\Python39\lib\site-packages\flask_login\utils.py", line 372, in _get_user
    current_app.login_manager._load_user()
  File "C:\Python\Python39\lib\site-packages\flask_login\login_manager.py", line 347, in _load_user
    raise Exception(
Exception: Missing user_loader or request_loader. Refer to http://flask-login.readthedocs.io/#how-it-works for more info.
2022-11-22 16:42:07,016 ERROR: Exception on / [GET] [in C:\Python\Python39\lib\site-packages\flask\app.py:1741]
Traceback (most recent call last):
  File "C:\Python\Python39\lib\site-packages\flask\app.py", line 2525, in wsgi_app
    response = self.full_dispatch_request()
  File "C:\Python\Python39\lib\site-packages\flask\app.py", line 1822, in full_dispatch_request
    rv = self.handle_user_exception(e)
  File "C:\Python\Python39\lib\site-packages\flask\app.py", line 1820, in full_dispatch_request
    rv = self.dispatch_request()
  File "C:\Python\Python39\lib\site-packages\flask\app.py", line 1796, in dispatch_request
    return self.ensure_sync(self.view_functions[rule.endpoint])(**view_args)
  File "D:\Assignments\Project Development Phase\Sprint 1\pet_App\app.py", line 62, in home
    return render_template('pages/placeholder.home.html')
  File "C:\Python\Python39\lib\site-packages\flask\templating.py", line 147, in render_template
    return _render(app, template, context)
  File "C:\Python\Python39\lib\site-packages\flask\templating.py", line 128, in _render
    app.update_template_context(context)
  File "C:\Python\Python39\lib\site-packages\flask\app.py", line 994, in update_template_context
    context.update(func())
  File "C:\Python\Python39\lib\site-packages\flask_login\utils.py", line 407, in _user_context_processor
    return dict(current_user=_get_user())
  File "C:\Python\Python39\lib\site-packages\flask_login\utils.py", line 372, in _get_user
    current_app.login_manager._load_user()
  File "C:\Python\Python39\lib\site-packages\flask_login\login_manager.py", line 347, in _load_user
    raise Exception(
Exception: Missing user_loader or request_loader. Refer to http://flask-login.readthedocs.io/#how-it-works for more info.
2022-11-22 16:42:38,281 INFO: errors [in D:\Assignments\Project Development Phase\Sprint 1\pet_App\app.py:45]
2022-11-22 16:42:39,283 ERROR: Exception on / [GET] [in C:\Python\Python39\lib\site-packages\flask\app.py:1741]
Traceback (most recent call last):
  File "C:\Python\Python39\lib\site-packages\flask\app.py", line 2525, in wsgi_app
    response = self.full_dispatch_request()
  File "C:\Python\Python39\lib\site-packages\flask\app.py", line 1822, in full_dispatch_request
    rv = self.handle_user_exception(e)
  File "C:\Python\Python39\lib\site-packages\flask\app.py", line 1820, in full_dispatch_request
    rv = self.dispatch_request()
  File "C:\Python\Python39\lib\site-packages\flask\app.py", line 1796, in dispatch_request
    return self.ensure_sync(self.view_functions[rule.endpoint])(**view_args)
  File "D:\Assignments\Project Development Phase\Sprint 1\pet_App\app.py", line 62, in home
    return render_template('pages/placeholder.home.html')
  File "C:\Python\Python39\lib\site-packages\flask\templating.py", line 147, in render_template
    return _render(app, template, context)
  File "C:\Python\Python39\lib\site-packages\flask\templating.py", line 128, in _render
    app.update_template_context(context)
  File "C:\Python\Python39\lib\site-packages\flask\app.py", line 994, in update_template_context
    context.update(func())
  File "C:\Python\Python39\lib\site-packages\flask_login\utils.py", line 407, in _user_context_processor
    return dict(current_user=_get_user())
  File "C:\Python\Python39\lib\site-packages\flask_login\utils.py", line 372, in _get_user
    current_app.login_manager._load_user()
  File "C:\Python\Python39\lib\site-packages\flask_login\login_manager.py", line 347, in _load_user
    raise Exception(
Exception: Missing user_loader or request_loader. Refer to http://flask-login.readthedocs.io/#how-it-works for more info.
2022-11-22 16:55:22,480 ERROR: Exception on / [GET] [in C:\Python\Python39\lib\site-packages\flask\app.py:1741]
Traceback (most recent call last):
  File "C:\Python\Python39\lib\site-packages\flask\app.py", line 2525, in wsgi_app
    response = self.full_dispatch_request()
  File "C:\Python\Python39\lib\site-packages\flask\app.py", line 1822, in full_dispatch_request
    rv = self.handle_user_exception(e)
  File "C:\Python\Python39\lib\site-packages\flask\app.py", line 1820, in full_dispatch_request
    rv = self.dispatch_request()
  File "C:\Python\Python39\lib\site-packages\flask\app.py", line 1796, in dispatch_request
    return self.ensure_sync(self.view_functions[rule.endpoint])(**view_args)
  File "D:\Assignments\Project Development Phase\Sprint 1\pet_App\app.py", line 62, in home
    return render_template('pages/placeholder.home.html')
  File "C:\Python\Python39\lib\site-packages\flask\templating.py", line 147, in render_template
    return _render(app, template, context)
  File "C:\Python\Python39\lib\site-packages\flask\templating.py", line 128, in _render
    app.update_template_context(context)
  File "C:\Python\Python39\lib\site-packages\flask\app.py", line 994, in update_template_context
    context.update(func())
  File "C:\Python\Python39\lib\site-packages\flask_login\utils.py", line 407, in _user_context_processor
    return dict(current_user=_get_user())
  File "C:\Python\Python39\lib\site-packages\flask_login\utils.py", line 372, in _get_user
    current_app.login_manager._load_user()
  File "C:\Python\Python39\lib\site-packages\flask_login\login_manager.py", line 347, in _load_user
    raise Exception(
Exception: Missing user_loader or request_loader. Refer to http://flask-login.readthedocs.io/#how-it-works for more info.
2022-11-22 16:55:24,919 ERROR: Exception on / [GET] [in C:\Python\Python39\lib\site-packages\flask\app.py:1741]
Traceback (most recent call last):
  File "C:\Python\Python39\lib\site-packages\flask\app.py", line 2525, in wsgi_app
    response = self.full_dispatch_request()
  File "C:\Python\Python39\lib\site-packages\flask\app.py", line 1822, in full_dispatch_request
    rv = self.handle_user_exception(e)
  File "C:\Python\Python39\lib\site-packages\flask\app.py", line 1820, in full_dispatch_request
    rv = self.dispatch_request()
  File "C:\Python\Python39\lib\site-packages\flask\app.py", line 1796, in dispatch_request
    return self.ensure_sync(self.view_functions[rule.endpoint])(**view_args)
  File "D:\Assignments\Project Development Phase\Sprint 1\pet_App\app.py", line 62, in home
    return render_template('pages/placeholder.home.html')
  File "C:\Python\Python39\lib\site-packages\flask\templating.py", line 147, in render_template
    return _render(app, template, context)
  File "C:\Python\Python39\lib\site-packages\flask\templating.py", line 128, in _render
    app.update_template_context(context)
  File "C:\Python\Python39\lib\site-packages\flask\app.py", line 994, in update_template_context
    context.update(func())
  File "C:\Python\Python39\lib\site-packages\flask_login\utils.py", line 407, in _user_context_processor
    return dict(current_user=_get_user())
  File "C:\Python\Python39\lib\site-packages\flask_login\utils.py", line 372, in _get_user
    current_app.login_manager._load_user()
  File "C:\Python\Python39\lib\site-packages\flask_login\login_manager.py", line 347, in _load_user
    raise Exception(
Exception: Missing user_loader or request_loader. Refer to http://flask-login.readthedocs.io/#how-it-works for more info.
2022-11-22 16:55:36,405 INFO: errors [in D:\Assignments\Project Development Phase\Sprint 1\pet_App\app.py:45]
2022-11-22 16:55:39,701 ERROR: Exception on / [GET] [in C:\Python\Python39\lib\site-packages\flask\app.py:1741]
Traceback (most recent call last):
  File "C:\Python\Python39\lib\site-packages\flask\app.py", line 2525, in wsgi_app
    response = self.full_dispatch_request()
  File "C:\Python\Python39\lib\site-packages\flask\app.py", line 1822, in full_dispatch_request
    rv = self.handle_user_exception(e)
  File "C:\Python\Python39\lib\site-packages\flask\app.py", line 1820, in full_dispatch_request
    rv = self.dispatch_request()
  File "C:\Python\Python39\lib\site-packages\flask\app.py", line 1796, in dispatch_request
    return self.ensure_sync(self.view_functions[rule.endpoint])(**view_args)
  File "D:\Assignments\Project Development Phase\Sprint 1\pet_App\app.py", line 62, in home
    return render_template('pages/placeholder.home.html')
  File "C:\Python\Python39\lib\site-packages\flask\templating.py", line 147, in render_template
    return _render(app, template, context)
  File "C:\Python\Python39\lib\site-packages\flask\templating.py", line 128, in _render
    app.update_template_context(context)
  File "C:\Python\Python39\lib\site-packages\flask\app.py", line 994, in update_template_context
    context.update(func())
  File "C:\Python\Python39\lib\site-packages\flask_login\utils.py", line 407, in _user_context_processor
    return dict(current_user=_get_user())
  File "C:\Python\Python39\lib\site-packages\flask_login\utils.py", line 372, in _get_user
    current_app.login_manager._load_user()
  File "C:\Python\Python39\lib\site-packages\flask_login\login_manager.py", line 347, in _load_user
    raise Exception(
Exception: Missing user_loader or request_loader. Refer to http://flask-login.readthedocs.io/#how-it-works for more info.
2022-11-22 16:59:48,573 INFO: errors [in D:\Assignments\Project Development Phase\Sprint 1\pet_App\app.py:45]
2022-11-22 16:59:50,798 ERROR: Exception on / [GET] [in C:\Python\Python39\lib\site-packages\flask\app.py:1741]
Traceback (most recent call last):
  File "C:\Python\Python39\lib\site-packages\flask\app.py", line 2525, in wsgi_app
    response = self.full_dispatch_request()
  File "C:\Python\Python39\lib\site-packages\flask\app.py", line 1822, in full_dispatch_request
    rv = self.handle_user_exception(e)
  File "C:\Python\Python39\lib\site-packages\flask\app.py", line 1820, in full_dispatch_request
    rv = self.dispatch_request()
  File "C:\Python\Python39\lib\site-packages\flask\app.py", line 1796, in dispatch_request
    return self.ensure_sync(self.view_functions[rule.endpoint])(**view_args)
  File "D:\Assignments\Project Development Phase\Sprint 1\pet_App\app.py", line 52, in home
    return render_template('pages/placeholder.home.html')
  File "C:\Python\Python39\lib\site-packages\flask\templating.py", line 147, in render_template
    return _render(app, template, context)
  File "C:\Python\Python39\lib\site-packages\flask\templating.py", line 128, in _render
    app.update_template_context(context)
  File "C:\Python\Python39\lib\site-packages\flask\app.py", line 994, in update_template_context
    context.update(func())
  File "C:\Python\Python39\lib\site-packages\flask_login\utils.py", line 407, in _user_context_processor
    return dict(current_user=_get_user())
  File "C:\Python\Python39\lib\site-packages\flask_login\utils.py", line 372, in _get_user
    current_app.login_manager._load_user()
  File "C:\Python\Python39\lib\site-packages\flask_login\login_manager.py", line 347, in _load_user
    raise Exception(
Exception: Missing user_loader or request_loader. Refer to http://flask-login.readthedocs.io/#how-it-works for more info.
2022-11-22 16:59:51,506 ERROR: Exception on / [GET] [in C:\Python\Python39\lib\site-packages\flask\app.py:1741]
Traceback (most recent call last):
  File "C:\Python\Python39\lib\site-packages\flask\app.py", line 2525, in wsgi_app
    response = self.full_dispatch_request()
  File "C:\Python\Python39\lib\site-packages\flask\app.py", line 1822, in full_dispatch_request
    rv = self.handle_user_exception(e)
  File "C:\Python\Python39\lib\site-packages\flask\app.py", line 1820, in full_dispatch_request
    rv = self.dispatch_request()
  File "C:\Python\Python39\lib\site-packages\flask\app.py", line 1796, in dispatch_request
    return self.ensure_sync(self.view_functions[rule.endpoint])(**view_args)
  File "D:\Assignments\Project Development Phase\Sprint 1\pet_App\app.py", line 52, in home
    return render_template('pages/placeholder.home.html')
  File "C:\Python\Python39\lib\site-packages\flask\templating.py", line 147, in render_template
    return _render(app, template, context)
  File "C:\Python\Python39\lib\site-packages\flask\templating.py", line 128, in _render
    app.update_template_context(context)
  File "C:\Python\Python39\lib\site-packages\flask\app.py", line 994, in update_template_context
    context.update(func())
  File "C:\Python\Python39\lib\site-packages\flask_login\utils.py", line 407, in _user_context_processor
    return dict(current_user=_get_user())
  File "C:\Python\Python39\lib\site-packages\flask_login\utils.py", line 372, in _get_user
    current_app.login_manager._load_user()
  File "C:\Python\Python39\lib\site-packages\flask_login\login_manager.py", line 347, in _load_user
    raise Exception(
Exception: Missing user_loader or request_loader. Refer to http://flask-login.readthedocs.io/#how-it-works for more info.
2022-11-22 16:59:51,730 ERROR: Exception on / [GET] [in C:\Python\Python39\lib\site-packages\flask\app.py:1741]
Traceback (most recent call last):
  File "C:\Python\Python39\lib\site-packages\flask\app.py", line 2525, in wsgi_app
    response = self.full_dispatch_request()
  File "C:\Python\Python39\lib\site-packages\flask\app.py", line 1822, in full_dispatch_request
    rv = self.handle_user_exception(e)
  File "C:\Python\Python39\lib\site-packages\flask\app.py", line 1820, in full_dispatch_request
    rv = self.dispatch_request()
  File "C:\Python\Python39\lib\site-packages\flask\app.py", line 1796, in dispatch_request
    return self.ensure_sync(self.view_functions[rule.endpoint])(**view_args)
  File "D:\Assignments\Project Development Phase\Sprint 1\pet_App\app.py", line 52, in home
    return render_template('pages/placeholder.home.html')
  File "C:\Python\Python39\lib\site-packages\flask\templating.py", line 147, in render_template
    return _render(app, template, context)
  File "C:\Python\Python39\lib\site-packages\flask\templating.py", line 128, in _render
    app.update_template_context(context)
  File "C:\Python\Python39\lib\site-packages\flask\app.py", line 994, in update_template_context
    context.update(func())
  File "C:\Python\Python39\lib\site-packages\flask_login\utils.py", line 407, in _user_context_processor
    return dict(current_user=_get_user())
  File "C:\Python\Python39\lib\site-packages\flask_login\utils.py", line 372, in _get_user
    current_app.login_manager._load_user()
  File "C:\Python\Python39\lib\site-packages\flask_login\login_manager.py", line 347, in _load_user
    raise Exception(
Exception: Missing user_loader or request_loader. Refer to http://flask-login.readthedocs.io/#how-it-works for more info.
2022-11-22 16:59:52,103 ERROR: Exception on / [GET] [in C:\Python\Python39\lib\site-packages\flask\app.py:1741]
Traceback (most recent call last):
  File "C:\Python\Python39\lib\site-packages\flask\app.py", line 2525, in wsgi_app
    response = self.full_dispatch_request()
  File "C:\Python\Python39\lib\site-packages\flask\app.py", line 1822, in full_dispatch_request
    rv = self.handle_user_exception(e)
  File "C:\Python\Python39\lib\site-packages\flask\app.py", line 1820, in full_dispatch_request
    rv = self.dispatch_request()
  File "C:\Python\Python39\lib\site-packages\flask\app.py", line 1796, in dispatch_request
    return self.ensure_sync(self.view_functions[rule.endpoint])(**view_args)
  File "D:\Assignments\Project Development Phase\Sprint 1\pet_App\app.py", line 52, in home
    return render_template('pages/placeholder.home.html')
  File "C:\Python\Python39\lib\site-packages\flask\templating.py", line 147, in render_template
    return _render(app, template, context)
  File "C:\Python\Python39\lib\site-packages\flask\templating.py", line 128, in _render
    app.update_template_context(context)
  File "C:\Python\Python39\lib\site-packages\flask\app.py", line 994, in update_template_context
    context.update(func())
  File "C:\Python\Python39\lib\site-packages\flask_login\utils.py", line 407, in _user_context_processor
    return dict(current_user=_get_user())
  File "C:\Python\Python39\lib\site-packages\flask_login\utils.py", line 372, in _get_user
    current_app.login_manager._load_user()
  File "C:\Python\Python39\lib\site-packages\flask_login\login_manager.py", line 347, in _load_user
    raise Exception(
Exception: Missing user_loader or request_loader. Refer to http://flask-login.readthedocs.io/#how-it-works for more info.
